Workbook

Sheet BANG TINH
B2: PHÂN BỔ NHÂN SỰ HOUSEKEEPING - QUEEN ANN HOTEL
B5: Ngày | D5: SL phòng OUT | F5: SL phòng IN-HOUSE | H5: Phòng khả dụng (auto)
B6: =TODAY() | D6: 39 | F6: 11 | H6: =MAX('DINH MUC'!C21-D6-F6+B9,0)
B8: SL phòng Arrival (check-in hôm nay) | D8: - trong đó Back-to-Back (trùng phòng OUT) | F8: ARR vào phòng trống (auto) | H8: Kiểm tra hợp lệ
B9: 17 | D9: 17 | F9: =MAX(B9-D9,0) | H9: =IF(D9>MIN(B9,D6),"⚠ B2B > OUT/ARR",IF(F9>MAX('DINH MUC'!C21-D6-F6,0),"⚠ ARR > phòng trống","OK"))
B11: Phòng trống thực sự hôm nay (auto) - không OUT, không IN-HOUSE, không ARR
B12: =MAX(MAX('DINH MUC'!C21-D6-F6,0)-F9,0)
B14: TỔNG ĐIỂM CÔNG VIỆC | D14: ĐIỂM MỖI NGƯỜI/CA | F14: SỐ NV CẦN DỌN PHÒNG | H14: NV HIỆN CÓ
B15: =D6*'DINH MUC'!C23+F6*'DINH MUC'!C24+F9*'DINH MUC'!C25 | D15: ='DINH MUC'!C27 | F15: =ROUNDUP(B15/D15,0) | H15: ='DINH MUC'!C18
B17: =IF(H15>=F15,"✓ ĐỦ NGƯỜI - dư "&(H15-F15)&" người","⚠ THIẾU "&(F15-H15)&" người - cần Sup làm phòng hoặc tăng ca")
B18: =IF(D9>0,"🔔 Có "&D9&" phòng OUT là Back-to-Back - ưu tiên làm xong TRƯỚC giờ nhận phòng chuẩn ("&'DINH MUC'!C12&")","")
B20: QUY ĐỔI ĐIỂM
B21: 🛏 1 phòng IN-HOUSE | D21: 1 điểm | F21: 🧹 1 phòng OUT | H21: ='DINH MUC'!C23&" điểm"
B22: 🔑 1 phòng ARR vào phòng trống | D22: =ROUND('DINH MUC'!C25,2)&" điểm" | F22: 🔁 ARR Back-to-Back | H22: 0 điểm (đã tính trong OUT)
B24: PHÂN CA - NHẬP SỐ NGƯỜI XẾP CHO TỪNG CA
B25: Ca | D25: Bắt đầu | E25: Kết thúc | F25: Số NV xếp | G25: Điểm khả dụng | H25: Mức tải
B26: Ca Sup | D26: 7:00 | E26: 15:00 | F26: 1 | G26: =F26*D15 | H26: =G26
B27: Ca 1 | D27: 6:30 | E27: 14:30 | F27: 1 | G27: =F27*D15 | H27: =G27
B28: Ca 2 | D28: 8:00 | E28: 16:00 | F28: 1 | G28: =F28*D15 | H28: =G28
B29: Ca 3 | D29: 8:00 | E29: 16:00 | F29: 0 | G29: =F29*D15 | H29: =G29
B30: Ca 4 | D30: 9:00 | E30: 17:00 | F30: 1 | G30: =F30*D15 | H30: =G30
B31: Ca 5 | D31: 10:00 | E31: 18:00 | F31: 0 | G31: =F31*D15 | H31: =G31
B32: TỔNG | F32: =SUM(F26:F31) | G32: =SUM(G26:G31)
B34: Ghi chú: đổi định mức thời gian ở tab 'DINH MUC'. Đổi số NV xếp ca ở cột 'Số NV xếp' phía trên để cân bằng với 'SỐ NV CẦN DỌN PHÒNG'.
B35: Khi OUT đông và Tổng NV hiện có < Số NV cần: Sup nên xuống làm phòng cùng NV (cộng thêm 1 người vào cột 'Số NV xếp' ở ca tương ứng).
B36: Arrival Back-to-Back (khách mới nhận đúng phòng vừa checkout) không cộng thêm điểm - đã tính trong OUT - nhưng cần xếp làm SỚM trong ca để kịp giờ nhận phòng.

Sheet DINH MUC
B1: ĐỊNH MỨC & GIẢ ĐỊNH (chỉnh 1 lần ở đây)
B3: Thời gian dọn 1 phòng OUT - cả cặp 2 người (phút) | C3: 22.5 | E3: TB của 20-25 phút/phòng
B4: Số người / cặp dọn OUT | C4: 2
B5: Thời gian dọn 1 phòng IN-HOUSE - 1 người (phút) | C5: 7.5 | E5: TB của 5-10 phút/phòng - ĐÂY LÀ 1 ĐƠN VỊ ĐIỂM CHUẨN
B6: Độ dài 1 ca làm việc (giờ) | C6: 8
B7: Ăn trưa (phút/ca) | C7: 30
B8: Họp đầu ca + WC/uống nước (phút/ca) | C8: 15
B9: Xuống kho lấy đồ + chờ thang máy (phút/ca) | C9: 40
B10: Làm PA cuối ca - không có PA riêng (phút/ca) | C10: 30
B11: Kiểm tra phòng trống trước khi giao khách Arrival - VC check (phút, 1 người) | C11: 5 | E11: Chỉ áp dụng cho ARR vào phòng đã sạch sẵn (không phải Back-to-Back)
B12: Giờ nhận phòng chuẩn (check-in time) | C12: 14:00
B13: Bộ đệm an toàn cho giờ Check-out/Check-in trễ hơn dự kiến (phút) | C13: 15 | E13: Đại diện cho xác suất khách check-out/in lệch giờ so với dự kiến
B14: Ngưỡng 'GẤP' - còn dư dưới bao nhiêu phút thì cảnh báo Gấp | C14: 15
B15: Ngưỡng 'CẦN CHÚ Ý' - còn dư dưới bao nhiêu phút thì nhắc chú ý | C15: 45
B16: Tổng số phòng khách sạn | C16: 57
B17: Phòng khóa nội bộ | C17: 1
B18: Tổng nhân sự HK hiện có (gồm Sup) | C18: 4
B20: --- CÁC GIÁ TRỊ TỰ TÍNH (không sửa) ---
B21: Phòng khả dụng | C21: ='DINH MUC'!C16-'DINH MUC'!C17
B22: 1 ĐIỂM = thời gian dọn 1 phòng IN-HOUSE | C22: ='DINH MUC'!C5
B23: Điểm / phòng OUT (quy đổi) | C23: =('DINH MUC'!C3*'DINH MUC'!C4)/'DINH MUC'!C5
B24: Điểm / phòng IN-HOUSE (quy đổi) | C24: ='DINH MUC'!C5/'DINH MUC'!C5
B25: Điểm / phòng ARR vào phòng trống - VC check (quy đổi) | C25: ='DINH MUC'!C11/'DINH MUC'!C5
B26: Phút làm việc thực tế còn lại / người / ca | C26: ='DINH MUC'!C6*60-'DINH MUC'!C7-'DINH MUC'!C8-'DINH MUC'!C9-'DINH MUC'!C10
B27: ĐIỂM mỗi người làm được / ca | C27: ='DINH MUC'!C26/'DINH MUC'!C5
B29: Cách quy đổi: chọn 'dọn 1 phòng IN-HOUSE (1 người)' làm 1 ĐƠN VỊ ĐIỂM chuẩn.
B30: Phòng OUT tốn nhiều công hơn (2 người x thời gian dài hơn) nên quy đổi ra nhiều điểm hơn.
B31: Arrival (ARR) = số phòng sẽ check-in trong ngày, gồm 2 loại: (1) Back-to-Back - khách mới nhận đúng phòng vừa checkout hôm nay (đã tính điểm trong OUT rồi, không cộng thêm, chỉ cần ưu tiên làm sớm); (2) ARR vào phòng trống - phòng đã sạch sẵn, chỉ cần kiểm tra nhanh (VC check) trước khi giao khách, được cộng thêm điểm riêng.
B32: Mọi tính toán ở tab 'BANG TINH' đều dựa trên các ô ĐÃ TÍNH này - đổi định mức phía trên, cả bảng sẽ tự cập nhật.

Sheet LICH TRINH PHONG
B2: ƯU TIÊN LÀM PHÒNG THEO GIỜ CHECK-OUT / CHECK-IN
B4: Đã merge dữ liệu Check-in/Check-out ngày 19 từ báo cáo (38 phòng, tầng 2-11). Điền thêm/sửa tay các dòng bên dưới nếu cần - bảng tự xếp thứ tự ưu tiên làm phòng.
B6: 🔴 RỦI RO - không kịp | D6: 🟠 GẤP - làm ngay | F6: 🟡 CẦN CHÚ Ý | H6: 🟢 AN TOÀN
B7: =COUNTIF($J$10:$J$54,"🔴 RỦI RO") | D7: =COUNTIF($J$10:$J$54,"🟠 GẤP") | F7: =COUNTIF($J$10:$J$54,"🟡 CẦN CHÚ Ý") | H7: =COUNTIF($J$10:$J$54,"🟢 AN TOÀN")
B9: STT | C9: Số phòng | D9: Giờ Check-out | E9: Giờ Check-in (ARR) | F9: Loại phòng (auto) | G9: Thời gian trống (phút) | H9: Thời gian cần (phút) | I9: Dư/Thiếu (phút) | J9: Mức độ ưu tiên | K9: Giờ trễ nhất phải bắt đầu | L9: Thứ tự làm trước
B10: 1 | C10: 202 | D10: 12:00 | E10: 14:00 | F10: =IF(AND(D10<>"",E10<>""),"🔁 Back-to-Back",IF(AND(D10<>"",E10=""),"🧹 OUT thường",IF(AND(D10="",E10<>""),"🔑 ARR vào phòng trống","-"))) | G10: =IF(F10="🔁 Back-to-Back",ROUND((E10-D10)*1440,0),"-") | H10: =IF(F10="🔁 Back-to-Back",'DINH MUC'!C3+'DINH MUC'!C13,IF(F10="🔑 ARR vào phòng trống",'DINH MUC'!C11+'DINH MUC'!C13,"-")) | I10: =IF(F10="🔁 Back-to-Back",ROUND(G10-H10,0),"-") | J10: =IF(F10<>"🔁 Back-to-Back","-",IF(I10<0,"🔴 RỦI RO",IF(I10<'DINH MUC'!C14,"🟠 GẤP",IF(I10<'DINH MUC'!C15,"🟡 CẦN CHÚ Ý","🟢 AN TOÀN")))) | K10: =IF(F10="🔁 Back-to-Back",E10-H10/1440,"-") | L10: =IF(F10="🔁 Back-to-Back",RANK(I10,$I$10:$I$54,1),"-")
B11: 2 | C11: 204 | D11: 8:30 | F11: =IF(AND(D11<>"",E11<>""),"🔁 Back-to-Back",IF(AND(D11<>"",E11=""),"🧹 OUT thường",IF(AND(D11="",E11<>""),"🔑 ARR vào phòng trống","-"))) | G11: =IF(F11="🔁 Back-to-Back",ROUND((E11-D11)*1440,0),"-") | H11: =IF(F11="🔁 Back-to-Back",'DINH MUC'!C3+'DINH MUC'!C13,IF(F11="🔑 ARR vào phòng trống",'DINH MUC'!C11+'DINH MUC'!C13,"-")) | I11: =IF(F11="🔁 Back-to-Back",ROUND(G11-H11,0),"-") | J11: =IF(F11<>"🔁 Back-to-Back","-",IF(I11<0,"🔴 RỦI RO",IF(I11<'DINH MUC'!C14,"🟠 GẤP",IF(I11<'DINH MUC'!C15,"🟡 CẦN CHÚ Ý","🟢 AN TOÀN")))) | K11: =IF(F11="🔁 Back-to-Back",E11-H11/1440,"-") | L11: =IF(F11="🔁 Back-to-Back",RANK(I11,$I$10:$I$54,1),"-")
B12: 3 | C12: 301 | D12: 12:00 | E12: 14:00 | F12: =IF(AND(D12<>"",E12<>""),"🔁 Back-to-Back",IF(AND(D12<>"",E12=""),"🧹 OUT thường",IF(AND(D12="",E12<>""),"🔑 ARR vào phòng trống","-"))) | G12: =IF(F12="🔁 Back-to-Back",ROUND((E12-D12)*1440,0),"-") | H12: =IF(F12="🔁 Back-to-Back",'DINH MUC'!C3+'DINH MUC'!C13,IF(F12="🔑 ARR vào phòng trống",'DINH MUC'!C11+'DINH MUC'!C13,"-")) | I12: =IF(F12="🔁 Back-to-Back",ROUND(G12-H12,0),"-") | J12: =IF(F12<>"🔁 Back-to-Back","-",IF(I12<0,"🔴 RỦI RO",IF(I12<'DINH MUC'!C14,"🟠 GẤP",IF(I12<'DINH MUC'!C15,"🟡 CẦN CHÚ Ý","🟢 AN TOÀN")))) | K12: =IF(F12="🔁 Back-to-Back",E12-H12/1440,"-") | L12: =IF(F12="🔁 Back-to-Back",RANK(I12,$I$10:$I$54,1),"-")
B13: 4 | C13: 302 | D13: 9:00 | E13: 15:00 | F13: =IF(AND(D13<>"",E13<>""),"🔁 Back-to-Back",IF(AND(D13<>"",E13=""),"🧹 OUT thường",IF(AND(D13="",E13<>""),"🔑 ARR vào phòng trống","-"))) | G13: =IF(F13="🔁 Back-to-Back",ROUND((E13-D13)*1440,0),"-") | H13: =IF(F13="🔁 Back-to-Back",'DINH MUC'!C3+'DINH MUC'!C13,IF(F13="🔑 ARR vào phòng trống",'DINH MUC'!C11+'DINH MUC'!C13,"-")) | I13: =IF(F13="🔁 Back-to-Back",ROUND(G13-H13,0),"-") | J13: =IF(F13<>"🔁 Back-to-Back","-",IF(I13<0,"🔴 RỦI RO",IF(I13<'DINH MUC'!C14,"🟠 GẤP",IF(I13<'DINH MUC'!C15,"🟡 CẦN CHÚ Ý","🟢 AN TOÀN")))) | K13: =IF(F13="🔁 Back-to-Back",E13-H13/1440,"-") | L13: =IF(F13="🔁 Back-to-Back",RANK(I13,$I$10:$I$54,1),"-")
B14: 5 | C14: 303 | D14: 9:00 | E14: 15:00 | F14: =IF(AND(D14<>"",E14<>""),"🔁 Back-to-Back",IF(AND(D14<>"",E14=""),"🧹 OUT thường",IF(AND(D14="",E14<>""),"🔑 ARR vào phòng trống","-"))) | G14: =IF(F14="🔁 Back-to-Back",ROUND((E14-D14)*1440,0),"-") | H14: =IF(F14="🔁 Back-to-Back",'DINH MUC'!C3+'DINH MUC'!C13,IF(F14="🔑 ARR vào phòng trống",'DINH MUC'!C11+'DINH MUC'!C13,"-")) | I14: =IF(F14="🔁 Back-to-Back",ROUND(G14-H14,0),"-") | J14: =IF(F14<>"🔁 Back-to-Back","-",IF(I14<0,"🔴 RỦI RO",IF(I14<'DINH MUC'!C14,"🟠 GẤP",IF(I14<'DINH MUC'!C15,"🟡 CẦN CHÚ Ý","🟢 AN TOÀN")))) | K14: =IF(F14="🔁 Back-to-Back",E14-H14/1440,"-") | L14: =IF(F14="🔁 Back-to-Back",RANK(I14,$I$10:$I$54,1),"-")
B15: 6 | C15: 304 | D15: 12:00 | F15: =IF(AND(D15<>"",E15<>""),"🔁 Back-to-Back",IF(AND(D15<>"",E15=""),"🧹 OUT thường",IF(AND(D15="",E15<>""),"🔑 ARR vào phòng trống","-"))) | G15: =IF(F15="🔁 Back-to-Back",ROUND((E15-D15)*1440,0),"-") | H15: =IF(F15="🔁 Back-to-Back",'DINH MUC'!C3+'DINH MUC'!C13,IF(F15="🔑 ARR vào phòng trống",'DINH MUC'!C11+'DINH MUC'!C13,"-")) | I15: =IF(F15="🔁 Back-to-Back",ROUND(G15-H15,0),"-") | J15: =IF(F15<>"🔁 Back-to-Back","-",IF(I15<0,"🔴 RỦI RO",IF(I15<'DINH MUC'!C14,"🟠 GẤP",IF(I15<'DINH MUC'!C15,"🟡 CẦN CHÚ Ý","🟢 AN TOÀN")))) | K15: =IF(F15="🔁 Back-to-Back",E15-H15/1440,"-") | L15: =IF(F15="🔁 Back-to-Back",RANK(I15,$I$10:$I$54,1),"-")
B16: 7 | C16: 306 | D16: 12:00 | F16: =IF(AND(D16<>"",E16<>""),"🔁 Back-to-Back",IF(AND(D16<>"",E16=""),"🧹 OUT thường",IF(AND(D16="",E16<>""),"🔑 ARR vào phòng trống","-"))) | G16: =IF(F16="🔁 Back-to-Back",ROUND((E16-D16)*1440,0),"-") | H16: =IF(F16="🔁 Back-to-Back",'DINH MUC'!C3+'DINH MUC'!C13,IF(F16="🔑 ARR vào phòng trống",'DINH MUC'!C11+'DINH MUC'!C13,"-")) | I16: =IF(F16="🔁 Back-to-Back",ROUND(G16-H16,0),"-") | J16: =IF(F16<>"🔁 Back-to-Back","-",IF(I16<0,"🔴 RỦI RO",IF(I16<'DINH MUC'!C14,"🟠 GẤP",IF(I16<'DINH MUC'!C15,"🟡 CẦN CHÚ Ý","🟢 AN TOÀN")))) | K16: =IF(F16="🔁 Back-to-Back",E16-H16/1440,"-") | L16: =IF(F16="🔁 Back-to-Back",RANK(I16,$I$10:$I$54,1),"-")
B17: 8 | C17: 401 | D17: 10:00 | E17: 14:00 | F17: =IF(AND(D17<>"",E17<>""),"🔁 Back-to-Back",IF(AND(D17<>"",E17=""),"🧹 OUT thường",IF(AND(D17="",E17<>""),"🔑 ARR vào phòng trống","-"))) | G17: =IF(F17="🔁 Back-to-Back",ROUND((E17-D17)*1440,0),"-") | H17: =IF(F17="🔁 Back-to-Back",'DINH MUC'!C3+'DINH MUC'!C13,IF(F17="🔑 ARR vào phòng trống",'DINH MUC'!C11+'DINH MUC'!C13,"-")) | I17: =IF(F17="🔁 Back-to-Back",ROUND(G17-H17,0),"-") | J17: =IF(F17<>"🔁 Back-to-Back","-",IF(I17<0,"🔴 RỦI RO",IF(I17<'DINH MUC'!C14,"🟠 GẤP",IF(I17<'DINH MUC'!C15,"🟡 CẦN CHÚ Ý","🟢 AN TOÀN")))) | K17: =IF(F17="🔁 Back-to-Back",E17-H17/1440,"-") | L17: =IF(F17="🔁 Back-to-Back",RANK(I17,$I$10:$I$54,1),"-")
B18: 9 | C18: 402 | D18: 18:00 | F18: =IF(AND(D18<>"",E18<>""),"🔁 Back-to-Back",IF(AND(D18<>"",E18=""),"🧹 OUT thường",IF(AND(D18="",E18<>""),"🔑 ARR vào phòng trống","-"))) | G18: =IF(F18="🔁 Back-to-Back",ROUND((E18-D18)*1440,0),"-") | H18: =IF(F18="🔁 Back-to-Back",'DINH MUC'!C3+'DINH MUC'!C13,IF(F18="🔑 ARR vào phòng trống",'DINH MUC'!C11+'DINH MUC'!C13,"-")) | I18: =IF(F18="🔁 Back-to-Back",ROUND(G18-H18,0),"-") | J18: =IF(F18<>"🔁 Back-to-Back","-",IF(I18<0,"🔴 RỦI RO",IF(I18<'DINH MUC'!C14,"🟠 GẤP",IF(I18<'DINH MUC'!C15,"🟡 CẦN CHÚ Ý","🟢 AN TOÀN")))) | K18: =IF(F18="🔁 Back-to-Back",E18-H18/1440,"-") | L18: =IF(F18="🔁 Back-to-Back",RANK(I18,$I$10:$I$54,1),"-")
B19: 10 | C19: 403 | D19: 9:00 | E19: 14:00 | F19: =IF(AND(D19<>"",E19<>""),"🔁 Back-to-Back",IF(AND(D19<>"",E19=""),"🧹 OUT thường",IF(AND(D19="",E19<>""),"🔑 ARR vào phòng trống","-"))) | G19: =IF(F19="🔁 Back-to-Back",ROUND((E19-D19)*1440,0),"-") | H19: =IF(F19="🔁 Back-to-Back",'DINH MUC'!C3+'DINH MUC'!C13,IF(F19="🔑 ARR vào phòng trống",'DINH MUC'!C11+'DINH MUC'!C13,"-")) | I19: =IF(F19="🔁 Back-to-Back",ROUND(G19-H19,0),"-") | J19: =IF(F19<>"🔁 Back-to-Back","-",IF(I19<0,"🔴 RỦI RO",IF(I19<'DINH MUC'!C14,"🟠 GẤP",IF(I19<'DINH MUC'!C15,"🟡 CẦN CHÚ Ý","🟢 AN TOÀN")))) | K19: =IF(F19="🔁 Back-to-Back",E19-H19/1440,"-") | L19: =IF(F19="🔁 Back-to-Back",RANK(I19,$I$10:$I$54,1),"-")
B20: 11 | C20: 405 | D20: 12:00 | F20: =IF(AND(D20<>"",E20<>""),"🔁 Back-to-Back",IF(AND(D20<>"",E20=""),"🧹 OUT thường",IF(AND(D20="",E20<>""),"🔑 ARR vào phòng trống","-"))) | G20: =IF(F20="🔁 Back-to-Back",ROUND((E20-D20)*1440,0),"-") | H20: =IF(F20="🔁 Back-to-Back",'DINH MUC'!C3+'DINH MUC'!C13,IF(F20="🔑 ARR vào phòng trống",'DINH MUC'!C11+'DINH MUC'!C13,"-")) | I20: =IF(F20="🔁 Back-to-Back",ROUND(G20-H20,0),"-") | J20: =IF(F20<>"🔁 Back-to-Back","-",IF(I20<0,"🔴 RỦI RO",IF(I20<'DINH MUC'!C14,"🟠 GẤP",IF(I20<'DINH MUC'!C15,"🟡 CẦN CHÚ Ý","🟢 AN TOÀN")))) | K20: =IF(F20="🔁 Back-to-Back",E20-H20/1440,"-") | L20: =IF(F20="🔁 Back-to-Back",RANK(I20,$I$10:$I$54,1),"-")
B21: 12 | C21: 406 | D21: 18:00 | F21: =IF(AND(D21<>"",E21<>""),"🔁 Back-to-Back",IF(AND(D21<>"",E21=""),"🧹 OUT thường",IF(AND(D21="",E21<>""),"🔑 ARR vào phòng trống","-"))) | G21: =IF(F21="🔁 Back-to-Back",ROUND((E21-D21)*1440,0),"-") | H21: =IF(F21="🔁 Back-to-Back",'DINH MUC'!C3+'DINH MUC'!C13,IF(F21="🔑 ARR vào phòng trống",'DINH MUC'!C11+'DINH MUC'!C13,"-")) | I21: =IF(F21="🔁 Back-to-Back",ROUND(G21-H21,0),"-") | J21: =IF(F21<>"🔁 Back-to-Back","-",IF(I21<0,"🔴 RỦI RO",IF(I21<'DINH MUC'!C14,"🟠 GẤP",IF(I21<'DINH MUC'!C15,"🟡 CẦN CHÚ Ý","🟢 AN TOÀN")))) | K21: =IF(F21="🔁 Back-to-Back",E21-H21/1440,"-") | L21: =IF(F21="🔁 Back-to-Back",RANK(I21,$I$10:$I$54,1),"-")
B22: 13 | C22: 501 | D22: 12:00 | E22: 14:00 | F22: =IF(AND(D22<>"",E22<>""),"🔁 Back-to-Back",IF(AND(D22<>"",E22=""),"🧹 OUT thường",IF(AND(D22="",E22<>""),"🔑 ARR vào phòng trống","-"))) | G22: =IF(F22="🔁 Back-to-Back",ROUND((E22-D22)*1440,0),"-") | H22: =IF(F22="🔁 Back-to-Back",'DINH MUC'!C3+'DINH MUC'!C13,IF(F22="🔑 ARR vào phòng trống",'DINH MUC'!C11+'DINH MUC'!C13,"-")) | I22: =IF(F22="🔁 Back-to-Back",ROUND(G22-H22,0),"-") | J22: =IF(F22<>"🔁 Back-to-Back","-",IF(I22<0,"🔴 RỦI RO",IF(I22<'DINH MUC'!C14,"🟠 GẤP",IF(I22<'DINH MUC'!C15,"🟡 CẦN CHÚ Ý","🟢 AN TOÀN")))) | K22: =IF(F22="🔁 Back-to-Back",E22-H22/1440,"-") | L22: =IF(F22="🔁 Back-to-Back",RANK(I22,$I$10:$I$54,1),"-")
B23: 14 | C23: 506 | D23: 9:00 | F23: =IF(AND(D23<>"",E23<>""),"🔁 Back-to-Back",IF(AND(D23<>"",E23=""),"🧹 OUT thường",IF(AND(D23="",E23<>""),"🔑 ARR vào phòng trống","-"))) | G23: =IF(F23="🔁 Back-to-Back",ROUND((E23-D23)*1440,0),"-") | H23: =IF(F23="🔁 Back-to-Back",'DINH MUC'!C3+'DINH MUC'!C13,IF(F23="🔑 ARR vào phòng trống",'DINH MUC'!C11+'DINH MUC'!C13,"-")) | I23: =IF(F23="🔁 Back-to-Back",ROUND(G23-H23,0),"-") | J23: =IF(F23<>"🔁 Back-to-Back","-",IF(I23<0,"🔴 RỦI RO",IF(I23<'DINH MUC'!C14,"🟠 GẤP",IF(I23<'DINH MUC'!C15,"🟡 CẦN CHÚ Ý","🟢 AN TOÀN")))) | K23: =IF(F23="🔁 Back-to-Back",E23-H23/1440,"-") | L23: =IF(F23="🔁 Back-to-Back",RANK(I23,$I$10:$I$54,1),"-")
B24: 15 | C24: 601 | D24: 12:00 | F24: =IF(AND(D24<>"",E24<>""),"🔁 Back-to-Back",IF(AND(D24<>"",E24=""),"🧹 OUT thường",IF(AND(D24="",E24<>""),"🔑 ARR vào phòng trống","-"))) | G24: =IF(F24="🔁 Back-to-Back",ROUND((E24-D24)*1440,0),"-") | H24: =IF(F24="🔁 Back-to-Back",'DINH MUC'!C3+'DINH MUC'!C13,IF(F24="🔑 ARR vào phòng trống",'DINH MUC'!C11+'DINH MUC'!C13,"-")) | I24: =IF(F24="🔁 Back-to-Back",ROUND(G24-H24,0),"-") | J24: =IF(F24<>"🔁 Back-to-Back","-",IF(I24<0,"🔴 RỦI RO",IF(I24<'DINH MUC'!C14,"🟠 GẤP",IF(I24<'DINH MUC'!C15,"🟡 CẦN CHÚ Ý","🟢 AN TOÀN")))) | K24: =IF(F24="🔁 Back-to-Back",E24-H24/1440,"-") | L24: =IF(F24="🔁 Back-to-Back",RANK(I24,$I$10:$I$54,1),"-")
B25: 16 | C25: 604 | D25: 9:00 | E25: 14:00 | F25: =IF(AND(D25<>"",E25<>""),"🔁 Back-to-Back",IF(AND(D25<>"",E25=""),"🧹 OUT thường",IF(AND(D25="",E25<>""),"🔑 ARR vào phòng trống","-"))) | G25: =IF(F25="🔁 Back-to-Back",ROUND((E25-D25)*1440,0),"-") | H25: =IF(F25="🔁 Back-to-Back",'DINH MUC'!C3+'DINH MUC'!C13,IF(F25="🔑 ARR vào phòng trống",'DINH MUC'!C11+'DINH MUC'!C13,"-")) | I25: =IF(F25="🔁 Back-to-Back",ROUND(G25-H25,0),"-") | J25: =IF(F25<>"🔁 Back-to-Back","-",IF(I25<0,"🔴 RỦI RO",IF(I25<'DINH MUC'!C14,"🟠 GẤP",IF(I25<'DINH MUC'!C15,"🟡 CẦN CHÚ Ý","🟢 AN TOÀN")))) | K25: =IF(F25="🔁 Back-to-Back",E25-H25/1440,"-") | L25: =IF(F25="🔁 Back-to-Back",RANK(I25,$I$10:$I$54,1),"-")
B26: 17 | C26: 605 | D26: 9:00 | E26: 14:00 | F26: =IF(AND(D26<>"",E26<>""),"🔁 Back-to-Back",IF(AND(D26<>"",E26=""),"🧹 OUT thường",IF(AND(D26="",E26<>""),"🔑 ARR vào phòng trống","-"))) | G26: =IF(F26="🔁 Back-to-Back",ROUND((E26-D26)*1440,0),"-") | H26: =IF(F26="🔁 Back-to-Back",'DINH MUC'!C3+'DINH MUC'!C13,IF(F26="🔑 ARR vào phòng trống",'DINH MUC'!C11+'DINH MUC'!C13,"-")) | I26: =IF(F26="🔁 Back-to-Back",ROUND(G26-H26,0),"-") | J26: =IF(F26<>"🔁 Back-to-Back","-",IF(I26<0,"🔴 RỦI RO",IF(I26<'DINH MUC'!C14,"🟠 GẤP",IF(I26<'DINH MUC'!C15,"🟡 CẦN CHÚ Ý","🟢 AN TOÀN")))) | K26: =IF(F26="🔁 Back-to-Back",E26-H26/1440,"-") | L26: =IF(F26="🔁 Back-to-Back",RANK(I26,$I$10:$I$54,1),"-")
B27: 18 | C27: 606 | D27: 12:00 | F27: =IF(AND(D27<>"",E27<>""),"🔁 Back-to-Back",IF(AND(D27<>"",E27=""),"🧹 OUT thường",IF(AND(D27="",E27<>""),"🔑 ARR vào phòng trống","-"))) | G27: =IF(F27="🔁 Back-to-Back",ROUND((E27-D27)*1440,0),"-") | H27: =IF(F27="🔁 Back-to-Back",'DINH MUC'!C3+'DINH MUC'!C13,IF(F27="🔑 ARR vào phòng trống",'DINH MUC'!C11+'DINH MUC'!C13,"-")) | I27: =IF(F27="🔁 Back-to-Back",ROUND(G27-H27,0),"-") | J27: =IF(F27<>"🔁 Back-to-Back","-",IF(I27<0,"🔴 RỦI RO",IF(I27<'DINH MUC'!C14,"🟠 GẤP",IF(I27<'DINH MUC'!C15,"🟡 CẦN CHÚ Ý","🟢 AN TOÀN")))) | K27: =IF(F27="🔁 Back-to-Back",E27-H27/1440,"-") | L27: =IF(F27="🔁 Back-to-Back",RANK(I27,$I$10:$I$54,1),"-")
B28: 19 | C28: 701 | D28: 12:00 | F28: =IF(AND(D28<>"",E28<>""),"🔁 Back-to-Back",IF(AND(D28<>"",E28=""),"🧹 OUT thường",IF(AND(D28="",E28<>""),"🔑 ARR vào phòng trống","-"))) | G28: =IF(F28="🔁 Back-to-Back",ROUND((E28-D28)*1440,0),"-") | H28: =IF(F28="🔁 Back-to-Back",'DINH MUC'!C3+'DINH MUC'!C13,IF(F28="🔑 ARR vào phòng trống",'DINH MUC'!C11+'DINH MUC'!C13,"-")) | I28: =IF(F28="🔁 Back-to-Back",ROUND(G28-H28,0),"-") | J28: =IF(F28<>"🔁 Back-to-Back","-",IF(I28<0,"🔴 RỦI RO",IF(I28<'DINH MUC'!C14,"🟠 GẤP",IF(I28<'DINH MUC'!C15,"🟡 CẦN CHÚ Ý","🟢 AN TOÀN")))) | K28: =IF(F28="🔁 Back-to-Back",E28-H28/1440,"-") | L28: =IF(F28="🔁 Back-to-Back",RANK(I28,$I$10:$I$54,1),"-")
B29: 20 | C29: 704 | D29: 9:00 | E29: 14:00 | F29: =IF(AND(D29<>"",E29<>""),"🔁 Back-to-Back",IF(AND(D29<>"",E29=""),"🧹 OUT thường",IF(AND(D29="",E29<>""),"🔑 ARR vào phòng trống","-"))) | G29: =IF(F29="🔁 Back-to-Back",ROUND((E29-D29)*1440,0),"-") | H29: =IF(F29="🔁 Back-to-Back",'DINH MUC'!C3+'DINH MUC'!C13,IF(F29="🔑 ARR vào phòng trống",'DINH MUC'!C11+'DINH MUC'!C13,"-")) | I29: =IF(F29="🔁 Back-to-Back",ROUND(G29-H29,0),"-") | J29: =IF(F29<>"🔁 Back-to-Back","-",IF(I29<0,"🔴 RỦI RO",IF(I29<'DINH MUC'!C14,"🟠 GẤP",IF(I29<'DINH MUC'!C15,"🟡 CẦN CHÚ Ý","🟢 AN TOÀN")))) | K29: =IF(F29="🔁 Back-to-Back",E29-H29/1440,"-") | L29: =IF(F29="🔁 Back-to-Back",RANK(I29,$I$10:$I$54,1),"-")
B30: 21 | C30: 705 | D30: 12:00 | F30: =IF(AND(D30<>"",E30<>""),"🔁 Back-to-Back",IF(AND(D30<>"",E30=""),"🧹 OUT thường",IF(AND(D30="",E30<>""),"🔑 ARR vào phòng trống","-"))) | G30: =IF(F30="🔁 Back-to-Back",ROUND((E30-D30)*1440,0),"-") | H30: =IF(F30="🔁 Back-to-Back",'DINH MUC'!C3+'DINH MUC'!C13,IF(F30="🔑 ARR vào phòng trống",'DINH MUC'!C11+'DINH MUC'!C13,"-")) | I30: =IF(F30="🔁 Back-to-Back",ROUND(G30-H30,0),"-") | J30: =IF(F30<>"🔁 Back-to-Back","-",IF(I30<0,"🔴 RỦI RO",IF(I30<'DINH MUC'!C14,"🟠 GẤP",IF(I30<'DINH MUC'!C15,"🟡 CẦN CHÚ Ý","🟢 AN TOÀN")))) | K30: =IF(F30="🔁 Back-to-Back",E30-H30/1440,"-") | L30: =IF(F30="🔁 Back-to-Back",RANK(I30,$I$10:$I$54,1),"-")
B31: 22 | C31: 706 | D31: 9:00 | F31: =IF(AND(D31<>"",E31<>""),"🔁 Back-to-Back",IF(AND(D31<>"",E31=""),"🧹 OUT thường",IF(AND(D31="",E31<>""),"🔑 ARR vào phòng trống","-"))) | G31: =IF(F31="🔁 Back-to-Back",ROUND((E31-D31)*1440,0),"-") | H31: =IF(F31="🔁 Back-to-Back",'DINH MUC'!C3+'DINH MUC'!C13,IF(F31="🔑 ARR vào phòng trống",'DINH MUC'!C11+'DINH MUC'!C13,"-")) | I31: =IF(F31="🔁 Back-to-Back",ROUND(G31-H31,0),"-") | J31: =IF(F31<>"🔁 Back-to-Back","-",IF(I31<0,"🔴 RỦI RO",IF(I31<'DINH MUC'!C14,"🟠 GẤP",IF(I31<'DINH MUC'!C15,"🟡 CẦN CHÚ Ý","🟢 AN TOÀN")))) | K31: =IF(F31="🔁 Back-to-Back",E31-H31/1440,"-") | L31: =IF(F31="🔁 Back-to-Back",RANK(I31,$I$10:$I$54,1),"-")
B32: 23 | C32: 801 | D32: 12:00 | F32: =IF(AND(D32<>"",E32<>""),"🔁 Back-to-Back",IF(AND(D32<>"",E32=""),"🧹 OUT thường",IF(AND(D32="",E32<>""),"🔑 ARR vào phòng trống","-"))) | G32: =IF(F32="🔁 Back-to-Back",ROUND((E32-D32)*1440,0),"-") | H32: =IF(F32="🔁 Back-to-Back",'DINH MUC'!C3+'DINH MUC'!C13,IF(F32="🔑 ARR vào phòng trống",'DINH MUC'!C11+'DINH MUC'!C13,"-")) | I32: =IF(F32="🔁 Back-to-Back",ROUND(G32-H32,0),"-") | J32: =IF(F32<>"🔁 Back-to-Back","-",IF(I32<0,"🔴 RỦI RO",IF(I32<'DINH MUC'!C14,"🟠 GẤP",IF(I32<'DINH MUC'!C15,"🟡 CẦN CHÚ Ý","🟢 AN TOÀN")))) | K32: =IF(F32="🔁 Back-to-Back",E32-H32/1440,"-") | L32: =IF(F32="🔁 Back-to-Back",RANK(I32,$I$10:$I$54,1),"-")
B33: 24 | C33: 803 | D33: 10:00 | E33: 14:00 | F33: =IF(AND(D33<>"",E33<>""),"🔁 Back-to-Back",IF(AND(D33<>"",E33=""),"🧹 OUT thường",IF(AND(D33="",E33<>""),"🔑 ARR vào phòng trống","-"))) | G33: =IF(F33="🔁 Back-to-Back",ROUND((E33-D33)*1440,0),"-") | H33: =IF(F33="🔁 Back-to-Back",'DINH MUC'!C3+'DINH MUC'!C13,IF(F33="🔑 ARR vào phòng trống",'DINH MUC'!C11+'DINH MUC'!C13,"-")) | I33: =IF(F33="🔁 Back-to-Back",ROUND(G33-H33,0),"-") | J33: =IF(F33<>"🔁 Back-to-Back","-",IF(I33<0,"🔴 RỦI RO",IF(I33<'DINH MUC'!C14,"🟠 GẤP",IF(I33<'DINH MUC'!C15,"🟡 CẦN CHÚ Ý","🟢 AN TOÀN")))) | K33: =IF(F33="🔁 Back-to-Back",E33-H33/1440,"-") | L33: =IF(F33="🔁 Back-to-Back",RANK(I33,$I$10:$I$54,1),"-")
B34: 25 | C34: 804 | D34: 8:30 | E34: 14:00 | F34: =IF(AND(D34<>"",E34<>""),"🔁 Back-to-Back",IF(AND(D34<>"",E34=""),"🧹 OUT thường",IF(AND(D34="",E34<>""),"🔑 ARR vào phòng trống","-"))) | G34: =IF(F34="🔁 Back-to-Back",ROUND((E34-D34)*1440,0),"-") | H34: =IF(F34="🔁 Back-to-Back",'DINH MUC'!C3+'DINH MUC'!C13,IF(F34="🔑 ARR vào phòng trống",'DINH MUC'!C11+'DINH MUC'!C13,"-")) | I34: =IF(F34="🔁 Back-to-Back",ROUND(G34-H34,0),"-") | J34: =IF(F34<>"🔁 Back-to-Back","-",IF(I34<0,"🔴 RỦI RO",IF(I34<'DINH MUC'!C14,"🟠 GẤP",IF(I34<'DINH MUC'!C15,"🟡 CẦN CHÚ Ý","🟢 AN TOÀN")))) | K34: =IF(F34="🔁 Back-to-Back",E34-H34/1440,"-") | L34: =IF(F34="🔁 Back-to-Back",RANK(I34,$I$10:$I$54,1),"-")
B35: 26 | C35: 805 | D35: 9:00 | F35: =IF(AND(D35<>"",E35<>""),"🔁 Back-to-Back",IF(AND(D35<>"",E35=""),"🧹 OUT thường",IF(AND(D35="",E35<>""),"🔑 ARR vào phòng trống","-"))) | G35: =IF(F35="🔁 Back-to-Back",ROUND((E35-D35)*1440,0),"-") | H35: =IF(F35="🔁 Back-to-Back",'DINH MUC'!C3+'DINH MUC'!C13,IF(F35="🔑 ARR vào phòng trống",'DINH MUC'!C11+'DINH MUC'!C13,"-")) | I35: =IF(F35="🔁 Back-to-Back",ROUND(G35-H35,0),"-") | J35: =IF(F35<>"🔁 Back-to-Back","-",IF(I35<0,"🔴 RỦI RO",IF(I35<'DINH MUC'!C14,"🟠 GẤP",IF(I35<'DINH MUC'!C15,"🟡 CẦN CHÚ Ý","🟢 AN TOÀN")))) | K35: =IF(F35="🔁 Back-to-Back",E35-H35/1440,"-") | L35: =IF(F35="🔁 Back-to-Back",RANK(I35,$I$10:$I$54,1),"-")
B36: 27 | C36: 901 | D36: 12:00 | F36: =IF(AND(D36<>"",E36<>""),"🔁 Back-to-Back",IF(AND(D36<>"",E36=""),"🧹 OUT thường",IF(AND(D36="",E36<>""),"🔑 ARR vào phòng trống","-"))) | G36: =IF(F36="🔁 Back-to-Back",ROUND((E36-D36)*1440,0),"-") | H36: =IF(F36="🔁 Back-to-Back",'DINH MUC'!C3+'DINH MUC'!C13,IF(F36="🔑 ARR vào phòng trống",'DINH MUC'!C11+'DINH MUC'!C13,"-")) | I36: =IF(F36="🔁 Back-to-Back",ROUND(G36-H36,0),"-") | J36: =IF(F36<>"🔁 Back-to-Back","-",IF(I36<0,"🔴 RỦI RO",IF(I36<'DINH MUC'!C14,"🟠 GẤP",IF(I36<'DINH MUC'!C15,"🟡 CẦN CHÚ Ý","🟢 AN TOÀN")))) | K36: =IF(F36="🔁 Back-to-Back",E36-H36/1440,"-") | L36: =IF(F36="🔁 Back-to-Back",RANK(I36,$I$10:$I$54,1),"-")
B37: 28 | C37: 902 | D37: 10:00 | E37: 14:00 | F37: =IF(AND(D37<>"",E37<>""),"🔁 Back-to-Back",IF(AND(D37<>"",E37=""),"🧹 OUT thường",IF(AND(D37="",E37<>""),"🔑 ARR vào phòng trống","-"))) | G37: =IF(F37="🔁 Back-to-Back",ROUND((E37-D37)*1440,0),"-") | H37: =IF(F37="🔁 Back-to-Back",'DINH MUC'!C3+'DINH MUC'!C13,IF(F37="🔑 ARR vào phòng trống",'DINH MUC'!C11+'DINH MUC'!C13,"-")) | I37: =IF(F37="🔁 Back-to-Back",ROUND(G37-H37,0),"-") | J37: =IF(F37<>"🔁 Back-to-Back","-",IF(I37<0,"🔴 RỦI RO",IF(I37<'DINH MUC'!C14,"🟠 GẤP",IF(I37<'DINH MUC'!C15,"🟡 CẦN CHÚ Ý","🟢 AN TOÀN")))) | K37: =IF(F37="🔁 Back-to-Back",E37-H37/1440,"-") | L37: =IF(F37="🔁 Back-to-Back",RANK(I37,$I$10:$I$54,1),"-")
B38: 29 | C38: 903 | D38: 10:00 | E38: 14:00 | F38: =IF(AND(D38<>"",E38<>""),"🔁 Back-to-Back",IF(AND(D38<>"",E38=""),"🧹 OUT thường",IF(AND(D38="",E38<>""),"🔑 ARR vào phòng trống","-"))) | G38: =IF(F38="🔁 Back-to-Back",ROUND((E38-D38)*1440,0),"-") | H38: =IF(F38="🔁 Back-to-Back",'DINH MUC'!C3+'DINH MUC'!C13,IF(F38="🔑 ARR vào phòng trống",'DINH MUC'!C11+'DINH MUC'!C13,"-")) | I38: =IF(F38="🔁 Back-to-Back",ROUND(G38-H38,0),"-") | J38: =IF(F38<>"🔁 Back-to-Back","-",IF(I38<0,"🔴 RỦI RO",IF(I38<'DINH MUC'!C14,"🟠 GẤP",IF(I38<'DINH MUC'!C15,"🟡 CẦN CHÚ Ý","🟢 AN TOÀN")))) | K38: =IF(F38="🔁 Back-to-Back",E38-H38/1440,"-") | L38: =IF(F38="🔁 Back-to-Back",RANK(I38,$I$10:$I$54,1),"-")
B39: 30 | C39: 904 | D39: 12:00 | E39: 14:00 | F39: =IF(AND(D39<>"",E39<>""),"🔁 Back-to-Back",IF(AND(D39<>"",E39=""),"🧹 OUT thường",IF(AND(D39="",E39<>""),"🔑 ARR vào phòng trống","-"))) | G39: =IF(F39="🔁 Back-to-Back",ROUND((E39-D39)*1440,0),"-") | H39: =IF(F39="🔁 Back-to-Back",'DINH MUC'!C3+'DINH MUC'!C13,IF(F39="🔑 ARR vào phòng trống",'DINH MUC'!C11+'DINH MUC'!C13,"-")) | I39: =IF(F39="🔁 Back-to-Back",ROUND(G39-H39,0),"-") | J39: =IF(F39<>"🔁 Back-to-Back","-",IF(I39<0,"🔴 RỦI RO",IF(I39<'DINH MUC'!C14,"🟠 GẤP",IF(I39<'DINH MUC'!C15,"🟡 CẦN CHÚ Ý","🟢 AN TOÀN")))) | K39: =IF(F39="🔁 Back-to-Back",E39-H39/1440,"-") | L39: =IF(F39="🔁 Back-to-Back",RANK(I39,$I$10:$I$54,1),"-")
B40: 31 | C40: 905 | D40: 9:00 | E40: 14:00 | F40: =IF(AND(D40<>"",E40<>""),"🔁 Back-to-Back",IF(AND(D40<>"",E40=""),"🧹 OUT thường",IF(AND(D40="",E40<>""),"🔑 ARR vào phòng trống","-"))) | G40: =IF(F40="🔁 Back-to-Back",ROUND((E40-D40)*1440,0),"-") | H40: =IF(F40="🔁 Back-to-Back",'DINH MUC'!C3+'DINH MUC'!C13,IF(F40="🔑 ARR vào phòng trống",'DINH MUC'!C11+'DINH MUC'!C13,"-")) | I40: =IF(F40="🔁 Back-to-Back",ROUND(G40-H40,0),"-") | J40: =IF(F40<>"🔁 Back-to-Back","-",IF(I40<0,"🔴 RỦI RO",IF(I40<'DINH MUC'!C14,"🟠 GẤP",IF(I40<'DINH MUC'!C15,"🟡 CẦN CHÚ Ý","🟢 AN TOÀN")))) | K40: =IF(F40="🔁 Back-to-Back",E40-H40/1440,"-") | L40: =IF(F40="🔁 Back-to-Back",RANK(I40,$I$10:$I$54,1),"-")
B41: 32 | C41: 1002 | D41: 12:00 | E41: 14:00 | F41: =IF(AND(D41<>"",E41<>""),"🔁 Back-to-Back",IF(AND(D41<>"",E41=""),"🧹 OUT thường",IF(AND(D41="",E41<>""),"🔑 ARR vào phòng trống","-"))) | G41: =IF(F41="🔁 Back-to-Back",ROUND((E41-D41)*1440,0),"-") | H41: =IF(F41="🔁 Back-to-Back",'DINH MUC'!C3+'DINH MUC'!C13,IF(F41="🔑 ARR vào phòng trống",'DINH MUC'!C11+'DINH MUC'!C13,"-")) | I41: =IF(F41="🔁 Back-to-Back",ROUND(G41-H41,0),"-") | J41: =IF(F41<>"🔁 Back-to-Back","-",IF(I41<0,"🔴 RỦI RO",IF(I41<'DINH MUC'!C14,"🟠 GẤP",IF(I41<'DINH MUC'!C15,"🟡 CẦN CHÚ Ý","🟢 AN TOÀN")))) | K41: =IF(F41="🔁 Back-to-Back",E41-H41/1440,"-") | L41: =IF(F41="🔁 Back-to-Back",RANK(I41,$I$10:$I$54,1),"-")
B42: 33 | C42: 1003 | D42: 10:00 | F42: =IF(AND(D42<>"",E42<>""),"🔁 Back-to-Back",IF(AND(D42<>"",E42=""),"🧹 OUT thường",IF(AND(D42="",E42<>""),"🔑 ARR vào phòng trống","-"))) | G42: =IF(F42="🔁 Back-to-Back",ROUND((E42-D42)*1440,0),"-") | H42: =IF(F42="🔁 Back-to-Back",'DINH MUC'!C3+'DINH MUC'!C13,IF(F42="🔑 ARR vào phòng trống",'DINH MUC'!C11+'DINH MUC'!C13,"-")) | I42: =IF(F42="🔁 Back-to-Back",ROUND(G42-H42,0),"-") | J42: =IF(F42<>"🔁 Back-to-Back","-",IF(I42<0,"🔴 RỦI RO",IF(I42<'DINH MUC'!C14,"🟠 GẤP",IF(I42<'DINH MUC'!C15,"🟡 CẦN CHÚ Ý","🟢 AN TOÀN")))) | K42: =IF(F42="🔁 Back-to-Back",E42-H42/1440,"-") | L42: =IF(F42="🔁 Back-to-Back",RANK(I42,$I$10:$I$54,1),"-")
B43: 34 | C43: 1004 | D43: 8:00 | F43: =IF(AND(D43<>"",E43<>""),"🔁 Back-to-Back",IF(AND(D43<>"",E43=""),"🧹 OUT thường",IF(AND(D43="",E43<>""),"🔑 ARR vào phòng trống","-"))) | G43: =IF(F43="🔁 Back-to-Back",ROUND((E43-D43)*1440,0),"-") | H43: =IF(F43="🔁 Back-to-Back",'DINH MUC'!C3+'DINH MUC'!C13,IF(F43="🔑 ARR vào phòng trống",'DINH MUC'!C11+'DINH MUC'!C13,"-")) | I43: =IF(F43="🔁 Back-to-Back",ROUND(G43-H43,0),"-") | J43: =IF(F43<>"🔁 Back-to-Back","-",IF(I43<0,"🔴 RỦI RO",IF(I43<'DINH MUC'!C14,"🟠 GẤP",IF(I43<'DINH MUC'!C15,"🟡 CẦN CHÚ Ý","🟢 AN TOÀN")))) | K43: =IF(F43="🔁 Back-to-Back",E43-H43/1440,"-") | L43: =IF(F43="🔁 Back-to-Back",RANK(I43,$I$10:$I$54,1),"-")
B44: 35 | C44: 1005 | D44: 12:00 | F44: =IF(AND(D44<>"",E44<>""),"🔁 Back-to-Back",IF(AND(D44<>"",E44=""),"🧹 OUT thường",IF(AND(D44="",E44<>""),"🔑 ARR vào phòng trống","-"))) | G44: =IF(F44="🔁 Back-to-Back",ROUND((E44-D44)*1440,0),"-") | H44: =IF(F44="🔁 Back-to-Back",'DINH MUC'!C3+'DINH MUC'!C13,IF(F44="🔑 ARR vào phòng trống",'DINH MUC'!C11+'DINH MUC'!C13,"-")) | I44: =IF(F44="🔁 Back-to-Back",ROUND(G44-H44,0),"-") | J44: =IF(F44<>"🔁 Back-to-Back","-",IF(I44<0,"🔴 RỦI RO",IF(I44<'DINH MUC'!C14,"🟠 GẤP",IF(I44<'DINH MUC'!C15,"🟡 CẦN CHÚ Ý","🟢 AN TOÀN")))) | K44: =IF(F44="🔁 Back-to-Back",E44-H44/1440,"-") | L44: =IF(F44="🔁 Back-to-Back",RANK(I44,$I$10:$I$54,1),"-")
...

Sheet XEP LICH LAM PHONG
B2: XẾP LỊCH & CHIA GIỜ LÀM PHÒNG THEO CẶP — QUEEN ANN HOTEL
B3: Xếp thứ tự làm từng phòng theo giờ Check-out / Check-in, chia giờ bắt đầu–kết thúc cho từng cặp, và cảnh báo phòng nào KHÔNG KỊP trước giờ nhận phòng. Sửa các ô màu vàng.
B4: Ô VÀNG = nhập tay (số phòng, giờ Check-out, giờ Check-in, số Cặp). Cột xám = tự tính bằng công thức. Định mức thời gian lấy từ tab 'DINH MUC'.
B6: THÔNG SỐ CA
B7: Số CẶP làm phòng (2 người/cặp) | E7: 2 | G7: Gợi ý = tổng NV / 2. Có 4 người ⇒ 2 cặp; Sup xuống làm ⇒ tăng lên.
B8: Giờ bắt đầu làm phòng (sớm nhất) | E8: 0.33333333 | G8: Ca sớm/giữa bắt đầu dọn OUT + Inhouse.
B9: Giờ nhận phòng chuẩn (hạn phòng OUT) | E9: 0.58333333 | G9: Phòng OUT không có ARR vẫn nên sạch trước giờ này để bán.
B10: Giờ kết thúc ca (hạn phòng Inhouse) | E10: 0.70833333 | G10: Phòng Inhouse ưu tiên thấp, làm xen kẽ, xong trước giờ này.
B12: TÓM TẮT (tự tính)
B13: 🔴 Không kịp | C13: =COUNTIF($N$16:$N$70,"🔴 Không kịp") | D13: 🟠 Sát giờ | E13: =COUNTIF($N$16:$N$70,"🟠 Sát giờ") | F13: 🟡 Chú ý | G13: =COUNTIF($N$16:$N$70,"🟡 Chú ý") | H13: 🟢 Kịp | I13: =COUNTIF($N$16:$N$70,"🟢 Kịp") | J13: Phòng cần dọn | K13: =COUNTA($C$16:$C$70) | L13: Giờ xong cuối | M13: =IF(COUNT($L$16:$L$70)=0,"",MAX($L$16:$L$70))
B14: =IF(C13>0,"⚠ Có "&C13&" phòng KHÔNG KỊP trước hạn với "&E7&" cặp — Sup nên xuống làm cùng (tăng ô Số cặp), hoặc dời bớt giờ nhận phòng/ưu tiên phòng ARR sớm.","✓ Đủ thời gian với "&E7&" cặp làm phòng.")
B15: STT | C15: Số phòng | D15: Giờ Check-out | E15: Giờ Check-in | F15: Loại (auto) | G15: Sẵn sàng | H15: Hạn chót | I15: Phút cần | J15: Cặp số | K15: Bắt đầu | L15: Xong | M15: Còn/Trễ (phút) | N15: Trạng thái | O15: Bắt đầu trễ nhất
B16: 1 | C16: 1004 | D16: 0.33333333 | F16: =IF($C16="","",IF(AND($D16<>"",$E16<>""),"🔁 B2B",IF($D16<>"","🧹 OUT",IF($E16<>"","🔑 ARR","🛏 Inhouse")))) | G16: =IF($C16="","",IF(OR($F16="🧹 OUT",$F16="🔁 B2B"),MAX($D16,$E$8),$E$8)) | H16: =IF($C16="","",IF($E16<>"",$E16,IF($F16="🧹 OUT",MAX($E$9,$D16),$E$10))) | I16: =IF($C16="","",IF(OR($F16="🧹 OUT",$F16="🔁 B2B"),'DINH MUC'!$C$3,IF($F16="🔑 ARR",'DINH MUC'!$C$11,'DINH MUC'!$C$5))) | J16: 1 | K16: =IF($C16="","",MAX($G16,_xlfn.MAXIFS($L$15:$L15,$J$15:$J15,$J16))) | L16: =IF($C16="","",$K16+$I16/1440) | M16: =IF($C16="","",ROUND(($H16-$L16)*1440,0)) | N16: =IF($C16="","",IF($M16<0,"🔴 Không kịp",IF($M16<'DINH MUC'!$C$14,"🟠 Sát giờ",IF($M16<'DINH MUC'!$C$15,"🟡 Chú ý","🟢 Kịp")))) | O16: =IF($C16="","",$H16-$I16/1440)
B17: 2 | C17: 1104 | D17: 0.33333333 | F17: =IF($C17="","",IF(AND($D17<>"",$E17<>""),"🔁 B2B",IF($D17<>"","🧹 OUT",IF($E17<>"","🔑 ARR","🛏 Inhouse")))) | G17: =IF($C17="","",IF(OR($F17="🧹 OUT",$F17="🔁 B2B"),MAX($D17,$E$8),$E$8)) | H17: =IF($C17="","",IF($E17<>"",$E17,IF($F17="🧹 OUT",MAX($E$9,$D17),$E$10))) | I17: =IF($C17="","",IF(OR($F17="🧹 OUT",$F17="🔁 B2B"),'DINH MUC'!$C$3,IF($F17="🔑 ARR",'DINH MUC'!$C$11,'DINH MUC'!$C$5))) | J17: 2 | K17: =IF($C17="","",MAX($G17,_xlfn.MAXIFS($L$15:$L16,$J$15:$J16,$J17))) | L17: =IF($C17="","",$K17+$I17/1440) | M17: =IF($C17="","",ROUND(($H17-$L17)*1440,0)) | N17: =IF($C17="","",IF($M17<0,"🔴 Không kịp",IF($M17<'DINH MUC'!$C$14,"🟠 Sát giờ",IF($M17<'DINH MUC'!$C$15,"🟡 Chú ý","🟢 Kịp")))) | O17: =IF($C17="","",$H17-$I17/1440)
B18: 3 | C18: 205 | F18: =IF($C18="","",IF(AND($D18<>"",$E18<>""),"🔁 B2B",IF($D18<>"","🧹 OUT",IF($E18<>"","🔑 ARR","🛏 Inhouse")))) | G18: =IF($C18="","",IF(OR($F18="🧹 OUT",$F18="🔁 B2B"),MAX($D18,$E$8),$E$8)) | H18: =IF($C18="","",IF($E18<>"",$E18,IF($F18="🧹 OUT",MAX($E$9,$D18),$E$10))) | I18: =IF($C18="","",IF(OR($F18="🧹 OUT",$F18="🔁 B2B"),'DINH MUC'!$C$3,IF($F18="🔑 ARR",'DINH MUC'!$C$11,'DINH MUC'!$C$5))) | J18: 1 | K18: =IF($C18="","",MAX($G18,_xlfn.MAXIFS($L$15:$L17,$J$15:$J17,$J18))) | L18: =IF($C18="","",$K18+$I18/1440) | M18: =IF($C18="","",ROUND(($H18-$L18)*1440,0)) | N18: =IF($C18="","",IF($M18<0,"🔴 Không kịp",IF($M18<'DINH MUC'!$C$14,"🟠 Sát giờ",IF($M18<'DINH MUC'!$C$15,"🟡 Chú ý","🟢 Kịp")))) | O18: =IF($C18="","",$H18-$I18/1440)
B19: 4 | C19: 305 | F19: =IF($C19="","",IF(AND($D19<>"",$E19<>""),"🔁 B2B",IF($D19<>"","🧹 OUT",IF($E19<>"","🔑 ARR","🛏 Inhouse")))) | G19: =IF($C19="","",IF(OR($F19="🧹 OUT",$F19="🔁 B2B"),MAX($D19,$E$8),$E$8)) | H19: =IF($C19="","",IF($E19<>"",$E19,IF($F19="🧹 OUT",MAX($E$9,$D19),$E$10))) | I19: =IF($C19="","",IF(OR($F19="🧹 OUT",$F19="🔁 B2B"),'DINH MUC'!$C$3,IF($F19="🔑 ARR",'DINH MUC'!$C$11,'DINH MUC'!$C$5))) | J19: 2 | K19: =IF($C19="","",MAX($G19,_xlfn.MAXIFS($L$15:$L18,$J$15:$J18,$J19))) | L19: =IF($C19="","",$K19+$I19/1440) | M19: =IF($C19="","",ROUND(($H19-$L19)*1440,0)) | N19: =IF($C19="","",IF($M19<0,"🔴 Không kịp",IF($M19<'DINH MUC'!$C$14,"🟠 Sát giờ",IF($M19<'DINH MUC'!$C$15,"🟡 Chú ý","🟢 Kịp")))) | O19: =IF($C19="","",$H19-$I19/1440)
B20: 5 | C20: 204 | D20: 0.35416667 | F20: =IF($C20="","",IF(AND($D20<>"",$E20<>""),"🔁 B2B",IF($D20<>"","🧹 OUT",IF($E20<>"","🔑 ARR","🛏 Inhouse")))) | G20: =IF($C20="","",IF(OR($F20="🧹 OUT",$F20="🔁 B2B"),MAX($D20,$E$8),$E$8)) | H20: =IF($C20="","",IF($E20<>"",$E20,IF($F20="🧹 OUT",MAX($E$9,$D20),$E$10))) | I20: =IF($C20="","",IF(OR($F20="🧹 OUT",$F20="🔁 B2B"),'DINH MUC'!$C$3,IF($F20="🔑 ARR",'DINH MUC'!$C$11,'DINH MUC'!$C$5))) | J20: 1 | K20: =IF($C20="","",MAX($G20,_xlfn.MAXIFS($L$15:$L19,$J$15:$J19,$J20))) | L20: =IF($C20="","",$K20+$I20/1440) | M20: =IF($C20="","",ROUND(($H20-$L20)*1440,0)) | N20: =IF($C20="","",IF($M20<0,"🔴 Không kịp",IF($M20<'DINH MUC'!$C$14,"🟠 Sát giờ",IF($M20<'DINH MUC'!$C$15,"🟡 Chú ý","🟢 Kịp")))) | O20: =IF($C20="","",$H20-$I20/1440)
B21: 6 | C21: 804 | D21: 0.35416667 | E21: 0.58333333 | F21: =IF($C21="","",IF(AND($D21<>"",$E21<>""),"🔁 B2B",IF($D21<>"","🧹 OUT",IF($E21<>"","🔑 ARR","🛏 Inhouse")))) | G21: =IF($C21="","",IF(OR($F21="🧹 OUT",$F21="🔁 B2B"),MAX($D21,$E$8),$E$8)) | H21: =IF($C21="","",IF($E21<>"",$E21,IF($F21="🧹 OUT",MAX($E$9,$D21),$E$10))) | I21: =IF($C21="","",IF(OR($F21="🧹 OUT",$F21="🔁 B2B"),'DINH MUC'!$C$3,IF($F21="🔑 ARR",'DINH MUC'!$C$11,'DINH MUC'!$C$5))) | J21: 2 | K21: =IF($C21="","",MAX($G21,_xlfn.MAXIFS($L$15:$L20,$J$15:$J20,$J21))) | L21: =IF($C21="","",$K21+$I21/1440) | M21: =IF($C21="","",ROUND(($H21-$L21)*1440,0)) | N21: =IF($C21="","",IF($M21<0,"🔴 Không kịp",IF($M21<'DINH MUC'!$C$14,"🟠 Sát giờ",IF($M21<'DINH MUC'!$C$15,"🟡 Chú ý","🟢 Kịp")))) | O21: =IF($C21="","",$H21-$I21/1440)
B22: 7 | C22: 404 | F22: =IF($C22="","",IF(AND($D22<>"",$E22<>""),"🔁 B2B",IF($D22<>"","🧹 OUT",IF($E22<>"","🔑 ARR","🛏 Inhouse")))) | G22: =IF($C22="","",IF(OR($F22="🧹 OUT",$F22="🔁 B2B"),MAX($D22,$E$8),$E$8)) | H22: =IF($C22="","",IF($E22<>"",$E22,IF($F22="🧹 OUT",MAX($E$9,$D22),$E$10))) | I22: =IF($C22="","",IF(OR($F22="🧹 OUT",$F22="🔁 B2B"),'DINH MUC'!$C$3,IF($F22="🔑 ARR",'DINH MUC'!$C$11,'DINH MUC'!$C$5))) | J22: 1 | K22: =IF($C22="","",MAX($G22,_xlfn.MAXIFS($L$15:$L21,$J$15:$J21,$J22))) | L22: =IF($C22="","",$K22+$I22/1440) | M22: =IF($C22="","",ROUND(($H22-$L22)*1440,0)) | N22: =IF($C22="","",IF($M22<0,"🔴 Không kịp",IF($M22<'DINH MUC'!$C$14,"🟠 Sát giờ",IF($M22<'DINH MUC'!$C$15,"🟡 Chú ý","🟢 Kịp")))) | O22: =IF($C22="","",$H22-$I22/1440)
B23: 8 | C23: 502 | F23: =IF($C23="","",IF(AND($D23<>"",$E23<>""),"🔁 B2B",IF($D23<>"","🧹 OUT",IF($E23<>"","🔑 ARR","🛏 Inhouse")))) | G23: =IF($C23="","",IF(OR($F23="🧹 OUT",$F23="🔁 B2B"),MAX($D23,$E$8),$E$8)) | H23: =IF($C23="","",IF($E23<>"",$E23,IF($F23="🧹 OUT",MAX($E$9,$D23),$E$10))) | I23: =IF($C23="","",IF(OR($F23="🧹 OUT",$F23="🔁 B2B"),'DINH MUC'!$C$3,IF($F23="🔑 ARR",'DINH MUC'!$C$11,'DINH MUC'!$C$5))) | J23: 2 | K23: =IF($C23="","",MAX($G23,_xlfn.MAXIFS($L$15:$L22,$J$15:$J22,$J23))) | L23: =IF($C23="","",$K23+$I23/1440) | M23: =IF($C23="","",ROUND(($H23-$L23)*1440,0)) | N23: =IF($C23="","",IF($M23<0,"🔴 Không kịp",IF($M23<'DINH MUC'!$C$14,"🟠 Sát giờ",IF($M23<'DINH MUC'!$C$15,"🟡 Chú ý","🟢 Kịp")))) | O23: =IF($C23="","",$H23-$I23/1440)
B24: 9 | C24: 403 | D24: 0.375 | E24: 0.58333333 | F24: =IF($C24="","",IF(AND($D24<>"",$E24<>""),"🔁 B2B",IF($D24<>"","🧹 OUT",IF($E24<>"","🔑 ARR","🛏 Inhouse")))) | G24: =IF($C24="","",IF(OR($F24="🧹 OUT",$F24="🔁 B2B"),MAX($D24,$E$8),$E$8)) | H24: =IF($C24="","",IF($E24<>"",$E24,IF($F24="🧹 OUT",MAX($E$9,$D24),$E$10))) | I24: =IF($C24="","",IF(OR($F24="🧹 OUT",$F24="🔁 B2B"),'DINH MUC'!$C$3,IF($F24="🔑 ARR",'DINH MUC'!$C$11,'DINH MUC'!$C$5))) | J24: 1 | K24: =IF($C24="","",MAX($G24,_xlfn.MAXIFS($L$15:$L23,$J$15:$J23,$J24))) | L24: =IF($C24="","",$K24+$I24/1440) | M24: =IF($C24="","",ROUND(($H24-$L24)*1440,0)) | N24: =IF($C24="","",IF($M24<0,"🔴 Không kịp",IF($M24<'DINH MUC'!$C$14,"🟠 Sát giờ",IF($M24<'DINH MUC'!$C$15,"🟡 Chú ý","🟢 Kịp")))) | O24: =IF($C24="","",$H24-$I24/1440)
B25: 10 | C25: 506 | D25: 0.375 | F25: =IF($C25="","",IF(AND($D25<>"",$E25<>""),"🔁 B2B",IF($D25<>"","🧹 OUT",IF($E25<>"","🔑 ARR","🛏 Inhouse")))) | G25: =IF($C25="","",IF(OR($F25="🧹 OUT",$F25="🔁 B2B"),MAX($D25,$E$8),$E$8)) | H25: =IF($C25="","",IF($E25<>"",$E25,IF($F25="🧹 OUT",MAX($E$9,$D25),$E$10))) | I25: =IF($C25="","",IF(OR($F25="🧹 OUT",$F25="🔁 B2B"),'DINH MUC'!$C$3,IF($F25="🔑 ARR",'DINH MUC'!$C$11,'DINH MUC'!$C$5))) | J25: 2 | K25: =IF($C25="","",MAX($G25,_xlfn.MAXIFS($L$15:$L24,$J$15:$J24,$J25))) | L25: =IF($C25="","",$K25+$I25/1440) | M25: =IF($C25="","",ROUND(($H25-$L25)*1440,0)) | N25: =IF($C25="","",IF($M25<0,"🔴 Không kịp",IF($M25<'DINH MUC'!$C$14,"🟠 Sát giờ",IF($M25<'DINH MUC'!$C$15,"🟡 Chú ý","🟢 Kịp")))) | O25: =IF($C25="","",$H25-$I25/1440)
B26: 11 | C26: 604 | D26: 0.375 | E26: 0.58333333 | F26: =IF($C26="","",IF(AND($D26<>"",$E26<>""),"🔁 B2B",IF($D26<>"","🧹 OUT",IF($E26<>"","🔑 ARR","🛏 Inhouse")))) | G26: =IF($C26="","",IF(OR($F26="🧹 OUT",$F26="🔁 B2B"),MAX($D26,$E$8),$E$8)) | H26: =IF($C26="","",IF($E26<>"",$E26,IF($F26="🧹 OUT",MAX($E$9,$D26),$E$10))) | I26: =IF($C26="","",IF(OR($F26="🧹 OUT",$F26="🔁 B2B"),'DINH MUC'!$C$3,IF($F26="🔑 ARR",'DINH MUC'!$C$11,'DINH MUC'!$C$5))) | J26: 1 | K26: =IF($C26="","",MAX($G26,_xlfn.MAXIFS($L$15:$L25,$J$15:$J25,$J26))) | L26: =IF($C26="","",$K26+$I26/1440) | M26: =IF($C26="","",ROUND(($H26-$L26)*1440,0)) | N26: =IF($C26="","",IF($M26<0,"🔴 Không kịp",IF($M26<'DINH MUC'!$C$14,"🟠 Sát giờ",IF($M26<'DINH MUC'!$C$15,"🟡 Chú ý","🟢 Kịp")))) | O26: =IF($C26="","",$H26-$I26/1440)
B27: 12 | C27: 605 | D27: 0.375 | E27: 0.58333333 | F27: =IF($C27="","",IF(AND($D27<>"",$E27<>""),"🔁 B2B",IF($D27<>"","🧹 OUT",IF($E27<>"","🔑 ARR","🛏 Inhouse")))) | G27: =IF($C27="","",IF(OR($F27="🧹 OUT",$F27="🔁 B2B"),MAX($D27,$E$8),$E$8)) | H27: =IF($C27="","",IF($E27<>"",$E27,IF($F27="🧹 OUT",MAX($E$9,$D27),$E$10))) | I27: =IF($C27="","",IF(OR($F27="🧹 OUT",$F27="🔁 B2B"),'DINH MUC'!$C$3,IF($F27="🔑 ARR",'DINH MUC'!$C$11,'DINH MUC'!$C$5))) | J27: 2 | K27: =IF($C27="","",MAX($G27,_xlfn.MAXIFS($L$15:$L26,$J$15:$J26,$J27))) | L27: =IF($C27="","",$K27+$I27/1440) | M27: =IF($C27="","",ROUND(($H27-$L27)*1440,0)) | N27: =IF($C27="","",IF($M27<0,"🔴 Không kịp",IF($M27<'DINH MUC'!$C$14,"🟠 Sát giờ",IF($M27<'DINH MUC'!$C$15,"🟡 Chú ý","🟢 Kịp")))) | O27: =IF($C27="","",$H27-$I27/1440)
B28: 13 | C28: 704 | D28: 0.375 | E28: 0.58333333 | F28: =IF($C28="","",IF(AND($D28<>"",$E28<>""),"🔁 B2B",IF($D28<>"","🧹 OUT",IF($E28<>"","🔑 ARR","🛏 Inhouse")))) | G28: =IF($C28="","",IF(OR($F28="🧹 OUT",$F28="🔁 B2B"),MAX($D28,$E$8),$E$8)) | H28: =IF($C28="","",IF($E28<>"",$E28,IF($F28="🧹 OUT",MAX($E$9,$D28),$E$10))) | I28: =IF($C28="","",IF(OR($F28="🧹 OUT",$F28="🔁 B2B"),'DINH MUC'!$C$3,IF($F28="🔑 ARR",'DINH MUC'!$C$11,'DINH MUC'!$C$5))) | J28: 1 | K28: =IF($C28="","",MAX($G28,_xlfn.MAXIFS($L$15:$L27,$J$15:$J27,$J28))) | L28: =IF($C28="","",$K28+$I28/1440) | M28: =IF($C28="","",ROUND(($H28-$L28)*1440,0)) | N28: =IF($C28="","",IF($M28<0,"🔴 Không kịp",IF($M28<'DINH MUC'!$C$14,"🟠 Sát giờ",IF($M28<'DINH MUC'!$C$15,"🟡 Chú ý","🟢 Kịp")))) | O28: =IF($C28="","",$H28-$I28/1440)
B29: 14 | C29: 706 | D29: 0.375 | F29: =IF($C29="","",IF(AND($D29<>"",$E29<>""),"🔁 B2B",IF($D29<>"","🧹 OUT",IF($E29<>"","🔑 ARR","🛏 Inhouse")))) | G29: =IF($C29="","",IF(OR($F29="🧹 OUT",$F29="🔁 B2B"),MAX($D29,$E$8),$E$8)) | H29: =IF($C29="","",IF($E29<>"",$E29,IF($F29="🧹 OUT",MAX($E$9,$D29),$E$10))) | I29: =IF($C29="","",IF(OR($F29="🧹 OUT",$F29="🔁 B2B"),'DINH MUC'!$C$3,IF($F29="🔑 ARR",'DINH MUC'!$C$11,'DINH MUC'!$C$5))) | J29: 2 | K29: =IF($C29="","",MAX($G29,_xlfn.MAXIFS($L$15:$L28,$J$15:$J28,$J29))) | L29: =IF($C29="","",$K29+$I29/1440) | M29: =IF($C29="","",ROUND(($H29-$L29)*1440,0)) | N29: =IF($C29="","",IF($M29<0,"🔴 Không kịp",IF($M29<'DINH MUC'!$C$14,"🟠 Sát giờ",IF($M29<'DINH MUC'!$C$15,"🟡 Chú ý","🟢 Kịp")))) | O29: =IF($C29="","",$H29-$I29/1440)
B30: 15 | C30: 805 | D30: 0.375 | F30: =IF($C30="","",IF(AND($D30<>"",$E30<>""),"🔁 B2B",IF($D30<>"","🧹 OUT",IF($E30<>"","🔑 ARR","🛏 Inhouse")))) | G30: =IF($C30="","",IF(OR($F30="🧹 OUT",$F30="🔁 B2B"),MAX($D30,$E$8),$E$8)) | H30: =IF($C30="","",IF($E30<>"",$E30,IF($F30="🧹 OUT",MAX($E$9,$D30),$E$10))) | I30: =IF($C30="","",IF(OR($F30="🧹 OUT",$F30="🔁 B2B"),'DINH MUC'!$C$3,IF($F30="🔑 ARR",'DINH MUC'!$C$11,'DINH MUC'!$C$5))) | J30: 1 | K30: =IF($C30="","",MAX($G30,_xlfn.MAXIFS($L$15:$L29,$J$15:$J29,$J30))) | L30: =IF($C30="","",$K30+$I30/1440) | M30: =IF($C30="","",ROUND(($H30-$L30)*1440,0)) | N30: =IF($C30="","",IF($M30<0,"🔴 Không kịp",IF($M30<'DINH MUC'!$C$14,"🟠 Sát giờ",IF($M30<'DINH MUC'!$C$15,"🟡 Chú ý","🟢 Kịp")))) | O30: =IF($C30="","",$H30-$I30/1440)
B31: 16 | C31: 905 | D31: 0.375 | E31: 0.58333333 | F31: =IF($C31="","",IF(AND($D31<>"",$E31<>""),"🔁 B2B",IF($D31<>"","🧹 OUT",IF($E31<>"","🔑 ARR","🛏 Inhouse")))) | G31: =IF($C31="","",IF(OR($F31="🧹 OUT",$F31="🔁 B2B"),MAX($D31,$E$8),$E$8)) | H31: =IF($C31="","",IF($E31<>"",$E31,IF($F31="🧹 OUT",MAX($E$9,$D31),$E$10))) | I31: =IF($C31="","",IF(OR($F31="🧹 OUT",$F31="🔁 B2B"),'DINH MUC'!$C$3,IF($F31="🔑 ARR",'DINH MUC'!$C$11,'DINH MUC'!$C$5))) | J31: 2 | K31: =IF($C31="","",MAX($G31,_xlfn.MAXIFS($L$15:$L30,$J$15:$J30,$J31))) | L31: =IF($C31="","",$K31+$I31/1440) | M31: =IF($C31="","",ROUND(($H31-$L31)*1440,0)) | N31: =IF($C31="","",IF($M31<0,"🔴 Không kịp",IF($M31<'DINH MUC'!$C$14,"🟠 Sát giờ",IF($M31<'DINH MUC'!$C$15,"🟡 Chú ý","🟢 Kịp")))) | O31: =IF($C31="","",$H31-$I31/1440)
B32: 17 | C32: 1105 | D32: 0.375 | F32: =IF($C32="","",IF(AND($D32<>"",$E32<>""),"🔁 B2B",IF($D32<>"","🧹 OUT",IF($E32<>"","🔑 ARR","🛏 Inhouse")))) | G32: =IF($C32="","",IF(OR($F32="🧹 OUT",$F32="🔁 B2B"),MAX($D32,$E$8),$E$8)) | H32: =IF($C32="","",IF($E32<>"",$E32,IF($F32="🧹 OUT",MAX($E$9,$D32),$E$10))) | I32: =IF($C32="","",IF(OR($F32="🧹 OUT",$F32="🔁 B2B"),'DINH MUC'!$C$3,IF($F32="🔑 ARR",'DINH MUC'!$C$11,'DINH MUC'!$C$5))) | J32: 1 | K32: =IF($C32="","",MAX($G32,_xlfn.MAXIFS($L$15:$L31,$J$15:$J31,$J32))) | L32: =IF($C32="","",$K32+$I32/1440) | M32: =IF($C32="","",ROUND(($H32-$L32)*1440,0)) | N32: =IF($C32="","",IF($M32<0,"🔴 Không kịp",IF($M32<'DINH MUC'!$C$14,"🟠 Sát giờ",IF($M32<'DINH MUC'!$C$15,"🟡 Chú ý","🟢 Kịp")))) | O32: =IF($C32="","",$H32-$I32/1440)
B33: 18 | C33: 401 | D33: 0.41666667 | E33: 0.58333333 | F33: =IF($C33="","",IF(AND($D33<>"",$E33<>""),"🔁 B2B",IF($D33<>"","🧹 OUT",IF($E33<>"","🔑 ARR","🛏 Inhouse")))) | G33: =IF($C33="","",IF(OR($F33="🧹 OUT",$F33="🔁 B2B"),MAX($D33,$E$8),$E$8)) | H33: =IF($C33="","",IF($E33<>"",$E33,IF($F33="🧹 OUT",MAX($E$9,$D33),$E$10))) | I33: =IF($C33="","",IF(OR($F33="🧹 OUT",$F33="🔁 B2B"),'DINH MUC'!$C$3,IF($F33="🔑 ARR",'DINH MUC'!$C$11,'DINH MUC'!$C$5))) | J33: 2 | K33: =IF($C33="","",MAX($G33,_xlfn.MAXIFS($L$15:$L32,$J$15:$J32,$J33))) | L33: =IF($C33="","",$K33+$I33/1440) | M33: =IF($C33="","",ROUND(($H33-$L33)*1440,0)) | N33: =IF($C33="","",IF($M33<0,"🔴 Không kịp",IF($M33<'DINH MUC'!$C$14,"🟠 Sát giờ",IF($M33<'DINH MUC'!$C$15,"🟡 Chú ý","🟢 Kịp")))) | O33: =IF($C33="","",$H33-$I33/1440)
B34: 19 | C34: 803 | D34: 0.41666667 | E34: 0.58333333 | F34: =IF($C34="","",IF(AND($D34<>"",$E34<>""),"🔁 B2B",IF($D34<>"","🧹 OUT",IF($E34<>"","🔑 ARR","🛏 Inhouse")))) | G34: =IF($C34="","",IF(OR($F34="🧹 OUT",$F34="🔁 B2B"),MAX($D34,$E$8),$E$8)) | H34: =IF($C34="","",IF($E34<>"",$E34,IF($F34="🧹 OUT",MAX($E$9,$D34),$E$10))) | I34: =IF($C34="","",IF(OR($F34="🧹 OUT",$F34="🔁 B2B"),'DINH MUC'!$C$3,IF($F34="🔑 ARR",'DINH MUC'!$C$11,'DINH MUC'!$C$5))) | J34: 1 | K34: =IF($C34="","",MAX($G34,_xlfn.MAXIFS($L$15:$L33,$J$15:$J33,$J34))) | L34: =IF($C34="","",$K34+$I34/1440) | M34: =IF($C34="","",ROUND(($H34-$L34)*1440,0)) | N34: =IF($C34="","",IF($M34<0,"🔴 Không kịp",IF($M34<'DINH MUC'!$C$14,"🟠 Sát giờ",IF($M34<'DINH MUC'!$C$15,"🟡 Chú ý","🟢 Kịp")))) | O34: =IF($C34="","",$H34-$I34/1440)
B35: 20 | C35: 902 | D35: 0.41666667 | E35: 0.58333333 | F35: =IF($C35="","",IF(AND($D35<>"",$E35<>""),"🔁 B2B",IF($D35<>"","🧹 OUT",IF($E35<>"","🔑 ARR","🛏 Inhouse")))) | G35: =IF($C35="","",IF(OR($F35="🧹 OUT",$F35="🔁 B2B"),MAX($D35,$E$8),$E$8)) | H35: =IF($C35="","",IF($E35<>"",$E35,IF($F35="🧹 OUT",MAX($E$9,$D35),$E$10))) | I35: =IF($C35="","",IF(OR($F35="🧹 OUT",$F35="🔁 B2B"),'DINH MUC'!$C$3,IF($F35="🔑 ARR",'DINH MUC'!$C$11,'DINH MUC'!$C$5))) | J35: 2 | K35: =IF($C35="","",MAX($G35,_xlfn.MAXIFS($L$15:$L34,$J$15:$J34,$J35))) | L35: =IF($C35="","",$K35+$I35/1440) | M35: =IF($C35="","",ROUND(($H35-$L35)*1440,0)) | N35: =IF($C35="","",IF($M35<0,"🔴 Không kịp",IF($M35<'DINH MUC'!$C$14,"🟠 Sát giờ",IF($M35<'DINH MUC'!$C$15,"🟡 Chú ý","🟢 Kịp")))) | O35: =IF($C35="","",$H35-$I35/1440)
B36: 21 | C36: 903 | D36: 0.41666667 | E36: 0.58333333 | F36: =IF($C36="","",IF(AND($D36<>"",$E36<>""),"🔁 B2B",IF($D36<>"","🧹 OUT",IF($E36<>"","🔑 ARR","🛏 Inhouse")))) | G36: =IF($C36="","",IF(OR($F36="🧹 OUT",$F36="🔁 B2B"),MAX($D36,$E$8),$E$8)) | H36: =IF($C36="","",IF($E36<>"",$E36,IF($F36="🧹 OUT",MAX($E$9,$D36),$E$10))) | I36: =IF($C36="","",IF(OR($F36="🧹 OUT",$F36="🔁 B2B"),'DINH MUC'!$C$3,IF($F36="🔑 ARR",'DINH MUC'!$C$11,'DINH MUC'!$C$5))) | J36: 1 | K36: =IF($C36="","",MAX($G36,_xlfn.MAXIFS($L$15:$L35,$J$15:$J35,$J36))) | L36: =IF($C36="","",$K36+$I36/1440) | M36: =IF($C36="","",ROUND(($H36-$L36)*1440,0)) | N36: =IF($C36="","",IF($M36<0,"🔴 Không kịp",IF($M36<'DINH MUC'!$C$14,"🟠 Sát giờ",IF($M36<'DINH MUC'!$C$15,"🟡 Chú ý","🟢 Kịp")))) | O36: =IF($C36="","",$H36-$I36/1440)
B37: 22 | C37: 1003 | D37: 0.41666667 | F37: =IF($C37="","",IF(AND($D37<>"",$E37<>""),"🔁 B2B",IF($D37<>"","🧹 OUT",IF($E37<>"","🔑 ARR","🛏 Inhouse")))) | G37: =IF($C37="","",IF(OR($F37="🧹 OUT",$F37="🔁 B2B"),MAX($D37,$E$8),$E$8)) | H37: =IF($C37="","",IF($E37<>"",$E37,IF($F37="🧹 OUT",MAX($E$9,$D37),$E$10))) | I37: =IF($C37="","",IF(OR($F37="🧹 OUT",$F37="🔁 B2B"),'DINH MUC'!$C$3,IF($F37="🔑 ARR",'DINH MUC'!$C$11,'DINH MUC'!$C$5))) | J37: 2 | K37: =IF($C37="","",MAX($G37,_xlfn.MAXIFS($L$15:$L36,$J$15:$J36,$J37))) | L37: =IF($C37="","",$K37+$I37/1440) | M37: =IF($C37="","",ROUND(($H37-$L37)*1440,0)) | N37: =IF($C37="","",IF($M37<0,"🔴 Không kịp",IF($M37<'DINH MUC'!$C$14,"🟠 Sát giờ",IF($M37<'DINH MUC'!$C$15,"🟡 Chú ý","🟢 Kịp")))) | O37: =IF($C37="","",$H37-$I37/1440)
B38: 23 | C38: 1006 | D38: 0.41666667 | F38: =IF($C38="","",IF(AND($D38<>"",$E38<>""),"🔁 B2B",IF($D38<>"","🧹 OUT",IF($E38<>"","🔑 ARR","🛏 Inhouse")))) | G38: =IF($C38="","",IF(OR($F38="🧹 OUT",$F38="🔁 B2B"),MAX($D38,$E$8),$E$8)) | H38: =IF($C38="","",IF($E38<>"",$E38,IF($F38="🧹 OUT",MAX($E$9,$D38),$E$10))) | I38: =IF($C38="","",IF(OR($F38="🧹 OUT",$F38="🔁 B2B"),'DINH MUC'!$C$3,IF($F38="🔑 ARR",'DINH MUC'!$C$11,'DINH MUC'!$C$5))) | J38: 1 | K38: =IF($C38="","",MAX($G38,_xlfn.MAXIFS($L$15:$L37,$J$15:$J37,$J38))) | L38: =IF($C38="","",$K38+$I38/1440) | M38: =IF($C38="","",ROUND(($H38-$L38)*1440,0)) | N38: =IF($C38="","",IF($M38<0,"🔴 Không kịp",IF($M38<'DINH MUC'!$C$14,"🟠 Sát giờ",IF($M38<'DINH MUC'!$C$15,"🟡 Chú ý","🟢 Kịp")))) | O38: =IF($C38="","",$H38-$I38/1440)
B39: 24 | C39: 302 | D39: 0.375 | E39: 0.625 | F39: =IF($C39="","",IF(AND($D39<>"",$E39<>""),"🔁 B2B",IF($D39<>"","🧹 OUT",IF($E39<>"","🔑 ARR","🛏 Inhouse")))) | G39: =IF($C39="","",IF(OR($F39="🧹 OUT",$F39="🔁 B2B"),MAX($D39,$E$8),$E$8)) | H39: =IF($C39="","",IF($E39<>"",$E39,IF($F39="🧹 OUT",MAX($E$9,$D39),$E$10))) | I39: =IF($C39="","",IF(OR($F39="🧹 OUT",$F39="🔁 B2B"),'DINH MUC'!$C$3,IF($F39="🔑 ARR",'DINH MUC'!$C$11,'DINH MUC'!$C$5))) | J39: 2 | K39: =IF($C39="","",MAX($G39,_xlfn.MAXIFS($L$15:$L38,$J$15:$J38,$J39))) | L39: =IF($C39="","",$K39+$I39/1440) | M39: =IF($C39="","",ROUND(($H39-$L39)*1440,0)) | N39: =IF($C39="","",IF($M39<0,"🔴 Không kịp",IF($M39<'DINH MUC'!$C$14,"🟠 Sát giờ",IF($M39<'DINH MUC'!$C$15,"🟡 Chú ý","🟢 Kịp")))) | O39: =IF($C39="","",$H39-$I39/1440)
B40: 25 | C40: 202 | D40: 0.5 | E40: 0.58333333 | F40: =IF($C40="","",IF(AND($D40<>"",$E40<>""),"🔁 B2B",IF($D40<>"","🧹 OUT",IF($E40<>"","🔑 ARR","🛏 Inhouse")))) | G40: =IF($C40="","",IF(OR($F40="🧹 OUT",$F40="🔁 B2B"),MAX($D40,$E$8),$E$8)) | H40: =IF($C40="","",IF($E40<>"",$E40,IF($F40="🧹 OUT",MAX($E$9,$D40),$E$10))) | I40: =IF($C40="","",IF(OR($F40="🧹 OUT",$F40="🔁 B2B"),'DINH MUC'!$C$3,IF($F40="🔑 ARR",'DINH MUC'!$C$11,'DINH MUC'!$C$5))) | J40: 1 | K40: =IF($C40="","",MAX($G40,_xlfn.MAXIFS($L$15:$L39,$J$15:$J39,$J40))) | L40: =IF($C40="","",$K40+$I40/1440) | M40: =IF($C40="","",ROUND(($H40-$L40)*1440,0)) | N40: =IF($C40="","",IF($M40<0,"🔴 Không kịp",IF($M40<'DINH MUC'!$C$14,"🟠 Sát giờ",IF($M40<'DINH MUC'!$C$15,"🟡 Chú ý","🟢 Kịp")))) | O40: =IF($C40="","",$H40-$I40/1440)
B41: 26 | C41: 301 | D41: 0.5 | E41: 0.58333333 | F41: =IF($C41="","",IF(AND($D41<>"",$E41<>""),"🔁 B2B",IF($D41<>"","🧹 OUT",IF($E41<>"","🔑 ARR","🛏 Inhouse")))) | G41: =IF($C41="","",IF(OR($F41="🧹 OUT",$F41="🔁 B2B"),MAX($D41,$E$8),$E$8)) | H41: =IF($C41="","",IF($E41<>"",$E41,IF($F41="🧹 OUT",MAX($E$9,$D41),$E$10))) | I41: =IF($C41="","",IF(OR($F41="🧹 OUT",$F41="🔁 B2B"),'DINH MUC'!$C$3,IF($F41="🔑 ARR",'DINH MUC'!$C$11,'DINH MUC'!$C$5))) | J41: 2 | K41: =IF($C41="","",MAX($G41,_xlfn.MAXIFS($L$15:$L40,$J$15:$J40,$J41))) | L41: =IF($C41="","",$K41+$I41/1440) | M41: =IF($C41="","",ROUND(($H41-$L41)*1440,0)) | N41: =IF($C41="","",IF($M41<0,"🔴 Không kịp",IF($M41<'DINH MUC'!$C$14,"🟠 Sát giờ",IF($M41<'DINH MUC'!$C$15,"🟡 Chú ý","🟢 Kịp")))) | O41: =IF($C41="","",$H41-$I41/1440)
B42: 27 | C42: 304 | D42: 0.5 | F42: =IF($C42="","",IF(AND($D42<>"",$E42<>""),"🔁 B2B",IF($D42<>"","🧹 OUT",IF($E42<>"","🔑 ARR","🛏 Inhouse")))) | G42: =IF($C42="","",IF(OR($F42="🧹 OUT",$F42="🔁 B2B"),MAX($D42,$E$8),$E$8)) | H42: =IF($C42="","",IF($E42<>"",$E42,IF($F42="🧹 OUT",MAX($E$9,$D42),$E$10))) | I42: =IF($C42="","",IF(OR($F42="🧹 OUT",$F42="🔁 B2B"),'DINH MUC'!$C$3,IF($F42="🔑 ARR",'DINH MUC'!$C$11,'DINH MUC'!$C$5))) | J42: 1 | K42: =IF($C42="","",MAX($G42,_xlfn.MAXIFS($L$15:$L41,$J$15:$J41,$J42))) | L42: =IF($C42="","",$K42+$I42/1440) | M42: =IF($C42="","",ROUND(($H42-$L42)*1440,0)) | N42: =IF($C42="","",IF($M42<0,"🔴 Không kịp",IF($M42<'DINH MUC'!$C$14,"🟠 Sát giờ",IF($M42<'DINH MUC'!$C$15,"🟡 Chú ý","🟢 Kịp")))) | O42: =IF($C42="","",$H42-$I42/1440)
B43: 28 | C43: 306 | D43: 0.5 | F43: =IF($C43="","",IF(AND($D43<>"",$E43<>""),"🔁 B2B",IF($D43<>"","🧹 OUT",IF($E43<>"","🔑 ARR","🛏 Inhouse")))) | G43: =IF($C43="","",IF(OR($F43="🧹 OUT",$F43="🔁 B2B"),MAX($D43,$E$8),$E$8)) | H43: =IF($C43="","",IF($E43<>"",$E43,IF($F43="🧹 OUT",MAX($E$9,$D43),$E$10))) | I43: =IF($C43="","",IF(OR($F43="🧹 OUT",$F43="🔁 B2B"),'DINH MUC'!$C$3,IF($F43="🔑 ARR",'DINH MUC'!$C$11,'DINH MUC'!$C$5))) | J43: 2 | K43: =IF($C43="","",MAX($G43,_xlfn.MAXIFS($L$15:$L42,$J$15:$J42,$J43))) | L43: =IF($C43="","",$K43+$I43/1440) | M43: =IF($C43="","",ROUND(($H43-$L43)*1440,0)) | N43: =IF($C43="","",IF($M43<0,"🔴 Không kịp",IF($M43<'DINH MUC'!$C$14,"🟠 Sát giờ",IF($M43<'DINH MUC'!$C$15,"🟡 Chú ý","🟢 Kịp")))) | O43: =IF($C43="","",$H43-$I43/1440)
...
